Traceback (most recent call last):
  File "/home/user/miniconda3/envs/spider/lib/python3.9/site-packages/urllib3/connection.py", line 174, in _new_conn
    conn = connection.create_connection(
  File "/home/user/miniconda3/envs/spider/lib/python3.9/site-packages/urllib3/util/connection.py", line 95, in create_connection
    raise err
  File "/home/user/miniconda3/envs/spider/lib/python3.9/site-packages/urllib3/util/connection.py", line 85, in create_connection
    sock.connect(sa)
ConnectionRefusedError: [Errno 111] Connection refused
During handling of the above exception, another exception occurred:
Traceback (most recent call last):
  File "/home/user/miniconda3/envs/spider/lib/python3.9/site-packages/urllib3/connectionpool.py", line 703, in urlopen
    httplib_response = self._make_request(
  File "/home/user/miniconda3/envs/spider/lib/python3.9/site-packages/urllib3/connectionpool.py", line 398, in _make_request
    conn.request(method, url, **httplib_request_kw)
  File "/home/user/miniconda3/envs/spider/lib/python3.9/site-packages/urllib3/connection.py", line 239, in request
    super(HTTPConnection, self).request(method, url, body=body, headers=headers)
  File "/home/user/miniconda3/envs/spider/lib/python3.9/http/client.py", line 1285, in request
    self._send_request(method, url, body, headers, encode_chunked)
  File "/home/user/miniconda3/envs/spider/lib/python3.9/http/client.py", line 1331, in _send_request
    self.endheaders(body, encode_chunked=encode_chunked)
  File "/home/user/miniconda3/envs/spider/lib/python3.9/http/client.py", line 1280, in endheaders
    self._send_output(message_body, encode_chunked=encode_chunked)
  File "/home/user/miniconda3/envs/spider/lib/python3.9/http/client.py", line 1040, in _send_output
    self.send(msg)
  File "/home/user/miniconda3/envs/spider/lib/python3.9/http/client.py", line 980, in send
    self.connect()
  File "/home/user/miniconda3/envs/spider/lib/python3.9/site-packages/urllib3/connection.py", line 205, in connect
    conn = self._new_conn()
  File "/home/user/miniconda3/envs/spider/lib/python3.9/site-packages/urllib3/connection.py", line 186, in _new_conn
    raise NewConnectionError(
urllib3.exceptions.NewConnectionError: <urllib3.connection.HTTPConnection object at 0x7fea7c119af0>: Failed to establish a new connection: [Errno 111] Connection refused
During handling of the above exception, another exception occurred:
Traceback (most recent call last):
  File "/home/user/miniconda3/envs/spider/lib/python3.9/site-packages/requests/adapters.py", line 440, in send
    resp = conn.urlopen(
  File "/home/user/miniconda3/envs/spider/lib/python3.9/site-packages/urllib3/connectionpool.py", line 785, in urlopen
    retries = retries.increment(
  File "/home/user/miniconda3/envs/spider/lib/python3.9/site-packages/urllib3/util/retry.py", line 592, in increment
    raise MaxRetryError(_pool, url, error or ResponseError(cause))
urllib3.exceptions.MaxRetryError: HTTPConnectionPool(host='localhost', port=8087): Max retries exceeded with url: /url-in-queue-num (Caused by NewConnectionError('<urllib3.connection.HTTPConnection object at 0x7fea7c119af0>: Failed to establish a new connection: [Errno 111] Connection refused'))
During handling of the above exception, another exception occurred:
Traceback (most recent call last):
  File "/home/user/homework/HPC/ServerClientSpider/monitor.py", line 11, in <module>
    requests.get(urljoin(SERVER, '/url-in-queue-num')).json()['nums'],
  File "/home/user/miniconda3/envs/spider/lib/python3.9/site-packages/requests/api.py", line 75, in get
    return request('get', url, params=params, **kwargs)
  File "/home/user/miniconda3/envs/spider/lib/python3.9/site-packages/requests/api.py", line 61, in request
    return session.request(method=method, url=url, **kwargs)
  File "/home/user/miniconda3/envs/spider/lib/python3.9/site-packages/requests/sessions.py", line 529, in request
    resp = self.send(prep, **send_kwargs)
  File "/home/user/miniconda3/envs/spider/lib/python3.9/site-packages/requests/sessions.py", line 645, in send
    r = adapter.send(request, **kwargs)
  File "/home/user/miniconda3/envs/spider/lib/python3.9/site-packages/requests/adapters.py", line 519, in send
    raise ConnectionError(e, request=request)
requests.exceptions.ConnectionError: HTTPConnectionPool(host='localhost', port=8087): Max retries exceeded with url: /url-in-queue-num (Caused by NewConnectionError('<urllib3.connection.HTTPConnection object at 0x7fea7c119af0>: Failed to establish a new connection: [Errno 111] Connection refused'))